<?xml version="1.0"?>
<robot xmlns:xacro="http://www.ros.org/wiki/xacro" >

    <xacro:include filename="inertial_macros.xacro"/>
    
    <!-- TILTING JOINT -->
    <!-- FIXED PART -->
    <xacro:property name="tilting_fixed_length" value="0.4" />
    <xacro:property name="tilting_extension_length" value="0.2" />
    <xacro:property name="actuator_radius" value="0.02" />
    
    <joint name="tilting_fixed_joint" type="fixed">
        <origin xyz="0.1 0 0.06" rpy="0 ${-pi/10} 0"/>
        <parent link="arm_link"/>
        <child link="tilting_fixed_link"/>
        <axis xyz="1 0 0"/> 
    </joint>

    <xacro:property name="tilting_length" value="0.6" />
    <xacro:property name="arm_radius" value="0.02" />
    <link name="tilting_fixed_link">
        <visual>
            <origin xyz="0.085 0 0"/>
            <geometry>                
                <box size="${tilting_fixed_length} ${actuator_radius} ${actuator_radius}" />
            </geometry>
            <material name="orange" />
        </visual>
        <collision>
            <origin xyz="0.085 0 0"/>
            <geometry>
                <box size="${tilting_fixed_length} ${actuator_radius} ${actuator_radius}"/>
            </geometry>
        </collision>
        <xacro:inertial_box mass="0.075" x="${tilting_fixed_length}" y="${actuator_radius}" z = "${actuator_radius}">
            <origin xyz="0.085 0 0"/>
        </xacro:inertial_box>
    </link>
    
    <gazebo reference="tilting_fixed_link">
        <material>Gazebo/Blue</material>
    </gazebo>
    
    
    
    <!-- MOVING PART -->
    <joint name="tilting_joint" type="prismatic">
        <parent link="tilting_fixed_link"/>
        <child link="tilting_link"/>
        <origin xyz="0 0 0" rpy="0 0 0"/>
        <axis xyz="1 0 0"/>
        <limit lower="0.185" upper="0.385" velocity="100" effort="100"/>
    </joint>

    <link name="tilting_link">
        <visual>
            <origin xyz="0 0 0"/>
            <geometry>
                <box size="${tilting_extension_length} ${actuator_radius} ${actuator_radius}"/>
            </geometry>
            <material name="blue"/>
        </visual>
        <collision>
            <origin xyz="0 0 0"/>
            <geometry>
                <box size="${tilting_extension_length} ${actuator_radius} ${actuator_radius}"/>
            </geometry>
        </collision>
        <xacro:inertial_box mass="1.5" x="${tilting_extension_length}" y="${actuator_radius}" z="${actuator_radius}">
            <origin xyz="0 0 0" rpy="0 0 0"/>
        </xacro:inertial_box>
    </link>

    <gazebo reference="tilting_link">
        <material>Gazebo/Blue</material>
    </gazebo>


</robot>
